I'm sorry, but an uncaught exception occurred.

While running game code:
  File "game/script.rpy", line 203, in script
    anon "KOA! Get over here and help me pack up this gear."
Exception: Sayer 'anon' is not defined.

-- Full Traceback ------------------------------------------------------------

Full traceback:
  File "game/script.rpy", line 203, in script
    anon "KOA! Get over here and help me pack up this gear."
  File "/Users/noelkim/Downloads/renpy-8.3.4-sdk/renpy/ast.py", line 2579, in execute
    Say.execute(self)
  File "/Users/noelkim/Downloads/renpy-8.3.4-sdk/renpy/ast.py", line 581, in execute
    who = eval_who(self.who, self.who_fast)
  File "/Users/noelkim/Downloads/renpy-8.3.4-sdk/renpy/ast.py", line 470, in eval_who
    raise Exception("Sayer '%s' is not defined." % who)
Exception: Sayer 'anon' is not defined.

macOS-10.16-x86_64-i386-64bit x86_64
Ren'Py 8.3.4.24120703
WIREDMIND 1.0
Mon Jun 30 20:45:46 2025
